Workbook

Sheet Habitantes
B1: Region | C1: Habitantes
A2: CALI | B2: Sur | C2: 2280907
A3: ALCALA | B3: Norte | C3: 14177
A4: ANDALUCIA | B4: Centro | C4: 22878
A5: ANSERMANUEVO | B5: Norte | C5: 17533
A6: ARGELIA | B6: Norte | C6: 5242
A7: BOLIVAR | B7: Norte | C7: 15911
A8: BUENAVENTURA | B8: Occidente | C8: 315743
A9: GUADALAJARA DE BUGA | B9: Centro | C9: 130564
A10: BUGALAGRANDE | B10: Centro | C10: 24772
A11: CAICEDONIA | B11: Oriente | C11: 28879
A12: CALIMA | B12: Centro | C12: 18495
A13: CANDELARIA | B13: Sur | C13: 95413
... A43: ZARZAL | B43: Norte | C43: 42940

Sheet Homicidios
A1: cole_mcpio_ubicacion | B1: 2020 | C1: 2021 | D1: 2022 | E1: 2023 | F1: 2024
A2: CALI | B2: 46.735794 | C2: 52.698334 | D2: 43.228417 | E2: 44.061419 | F2: 41.650098
A3: ALCALA | B3: 77.590463 | C3: 91.69782 | D3: 105.80518 | E3: 134.01989 | F3: 119.91253
A4: ANDALUCIA | B4: 48.081126 | C4: 65.565172 | D4: 39.339103 | E4: 61.19416 | F4: 61.19416
A5: ANSERMANUEVO | B5: 74.145896 | C5: 68.442366 | D5: 205.3271 | E5: 245.25181 | F5: 245.25181
A6: ARGELIA | B6: 38.153377 | C6: 19.076688 | D6: 0 | E6: 76.306753 | F6: 95.383441
A7: BOLIVAR | B7: 50.279681 | C7: 37.709761 | D7: 31.4248 | E7: 31.4248 | F7: 157.124
A8: BUENAVENTURA | B8: 35.155174 | C8: 61.125662 | D8: 34.521747 | E8: 43.073006 | F8: 25.020349
A9: GUADALAJARA DE BUGA | B9: 45.954474 | C9: 58.209001 | D9: 68.165804 | E9: 56.677185 | F9: 65.102172
A10: BUGALAGRANDE | B10: 64.589052 | C10: 44.404973 | D10: 48.441789 | E10: 92.846762 | F10: 48.441789
A11: CAICEDONIA | B11: 58.866304 | C11: 62.329028 | D11: 55.40358 | E11: 83.105371 | F11: 55.40358
A12: CALIMA EL DARIEN | B12: 32.4412 | C12: 43.254934 | D12: 27.034334 | E12: 32.4412 | F12: 27.034334
... A43: ZARZAL | B43: 58.220773 | C43: 60.549604 | D43: 53.563111 | E43: 60.549604 | F43: 86.166744

Sheet Lesiones Personales
A1: cole_mcpio_ubicacion | B1: 2020 | C1: 2021 | D1: 2022 | E1: 2023 | F1: 2024
A2: CALI | B2: 206.27759 | C2: 214.16919 | D2: 181.24369 | E2: 201.93721 | F2: 202.68253
A3: ALCALA | B3: 183.39564 | C3: 162.23461 | D3: 225.71771 | E3: 176.34196 | F3: 218.66403
A4: ANDALUCIA | B4: 100.53326 | C4: 100.53326 | D4: 170.46945 | E4: 118.01731 | F4: 74.307195
A5: ANSERMANUEVO | B5: 85.552957 | C5: 91.256488 | D5: 193.92004 | E5: 131.1812 | F5: 159.69885
A6: ARGELIA | B6: 57.230065 | C6: 95.383441 | D6: 152.61351 | E6: 152.61351 | F6: 133.53682
A7: BOLIVAR | B7: 100.55936 | C7: 157.124 | D7: 169.69392 | E7: 226.25856 | F7: 169.69392
A8: BUENAVENTURA | B8: 83.295592 | C8: 123.20146 | D8: 102.6151 | E8: 118.76748 | F8: 72.210627
A9: GUADALAJARA DE BUGA | B9: 240.49508 | C9: 235.13373 | D9: 251.9837 | E9: 314.02224 | F9: 277.25866
A10: BUGALAGRANDE | B10: 193.76716 | C10: 129.1781 | D10: 278.54029 | E10: 169.54626 | F10: 185.69352
A11: CAICEDONIA | B11: 221.61432 | C11: 238.92794 | D11: 349.7351 | E11: 252.77884 | F11: 252.77884
A12: CALIMA EL DARIEN | B12: 162.206 | C12: 216.27467 | D12: 243.309 | E12: 286.56394 | F12: 254.12274
... A43: ZARZAL | B43: 167.67583 | C43: 274.80205 | D43: 284.11737 | E43: 207.26595 | F43: 239.86959

Sheet Violencia Intrafamiliar
A1: cole_mcpio_ubicacion | B1: 2020 | C1: 2021 | D1: 2022 | E1: 2023 | F1: 2024
A2: CALI | B2: 225.48048 | C2: 255.46855 | D2: 236.79177 | E2: 231.09228 | F2: 284.7113
A3: ALCALA | B3: 204.55668 | C3: 183.39564 | D3: 119.91253 | E3: 141.07357 | F3: 289.20082
A4: ANDALUCIA | B4: 113.6463 | C4: 218.55057 | D4: 157.35641 | E4: 310.34181 | F4: 249.14765
A5: ANSERMANUEVO | B5: 28.517652 | C5: 68.442366 | D5: 91.256488 | E5: 91.256488 | F5: 68.442366
A6: ARGELIA | B6: 190.76688 | C6: 305.22701 | D6: 114.46013 | E6: 19.076688 | F6: 76.306753
A7: BOLIVAR | B7: 106.84432 | C7: 119.41424 | D7: 182.26384 | E7: 270.25328 | F7: 188.5488
A8: BUENAVENTURA | B8: 99.131255 | C8: 75.37776 | D8: 63.025942 | E8: 73.160767 | F8: 86.462724
A9: GUADALAJARA DE BUGA | B9: 250.45189 | C9: 295.64045 | D9: 267.30186 | E9: 308.66089 | F9: 336.23357
A10: BUGALAGRANDE | B10: 92.846762 | C10: 149.36218 | D10: 121.10447 | E10: 141.28855 | F10: 201.84079
A11: CAICEDONIA | B11: 197.37526 | C11: 114.26988 | D11: 128.12078 | E11: 128.12078 | F11: 155.82257
A12: CALIMA EL DARIEN | B12: 118.95107 | C12: 189.24034 | D12: 162.206 | E12: 178.4266 | F12: 237.90214
... A43: ZARZAL | B43: 223.56777 | C43: 302.74802 | D43: 209.59478 | E43: 170.00466 | F43: 223.56777

Sheet Delitos Sexuales
A1: cole_mcpio_ubicacion | B1: 2020 | C1: 2021 | D1: 2022 | E1: 2023 | F1: 2024
A2: CALI | B2: 60.15151 | C2: 63.395833 | D2: 44.587526 | E2: 51.032331 | F2: 49.497853
A3: ALCALA | B3: 63.483106 | C3: 70.536785 | D3: 35.268392 | E3: 70.536785 | F3: 176.34196
A4: ANDALUCIA | B4: 61.19416 | C4: 74.307195 | D4: 65.565172 | E4: 87.420229 | F4: 39.339103
A5: ANSERMANUEVO | B5: 51.331774 | C5: 22.814122 | D5: 17.110591 | E5: 51.331774 | F5: 34.221183
A6: ARGELIA | B6: 38.153377 | C6: 114.46013 | D6: 19.076688 | E6: 57.230065 | F6: 38.153377
A7: BOLIVAR | B7: 75.419521 | C7: 69.134561 | D7: 43.994721 | E7: 56.564641 | F7: 37.709761
A8: BUENAVENTURA | B8: 38.322306 | C8: 33.571607 | D8: 32.938181 | E8: 36.105313 | F8: 35.471887
A9: GUADALAJARA DE BUGA | B9: 52.847646 | C9: 54.379461 | D9: 45.188567 | E9: 56.677185 | F9: 64.336264
A10: BUGALAGRANDE | B10: 56.515421 | C10: 44.404973 | D10: 52.478605 | E10: 68.625868 | F10: 60.552236
A11: CAICEDONIA | B11: 51.940857 | C11: 76.179923 | D11: 38.089962 | E11: 13.850895 | F11: 24.239066
A12: CALIMA EL DARIEN | B12: 75.696134 | C12: 59.475534 | D12: 75.696134 | E12: 37.848067 | F12: 70.289267
... A43: ZARZAL | B43: 48.905449 | C43: 60.549604 | D43: 34.932464 | E43: 30.274802 | F43: 41.918957

Sheet Extorsión
A1: cole_mcpio_ubicacion | B1: 2020 | C1: 2021 | D1: 2022 | E1: 2023 | F1: 2024
A2: CALI | B2: 26.086114 | C2: 24.858532 | D2: 15.388615 | E2: 20.518154 | F2: 20.737365
A3: ALCALA | B3: 14.107357 | C3: 7.0536785 | D3: 28.214714 | E3: 21.161035 | F3: 0
A4: ANDALUCIA | B4: 39.339103 | C4: 4.3710115 | D4: 13.113034 | E4: 17.484046 | F4: 26.226069
A5: ANSERMANUEVO | B5: 17.110591 | C5: 0 | D5: 28.517652 | E5: 11.407061 | F5: 17.110591
A6: ARGELIA | B6: 19.076688 | C6: 0 | D6: 0 | E6: 19.076688 | F6: 19.076688
A7: BOLIVAR | B7: 6.2849601 | C7: 0 | D7: 0 | E7: 6.2849601 | F7: 31.4248
A8: BUENAVENTURA | B8: 31.988041 | C8: 76.011186 | D8: 81.395312 | E8: 50.040698 | F8: 49.723984
A9: GUADALAJARA DE BUGA | B9: 22.211329 | C9: 11.488619 | D9: 19.913606 | E9: 16.849974 | F9: 32.93404
A10: BUGALAGRANDE | B10: 32.294526 | C10: 8.0736315 | D10: 20.184079 | E10: 24.220895 | F10: 40.368158
A11: CAICEDONIA | B11: 13.850895 | C11: 6.9254476 | D11: 10.388171 | E11: 6.9254476 | F11: 6.9254476
A12: CALIMA EL DARIEN | B12: 27.034334 | C12: 0 | D12: 21.627467 | E12: 27.034334 | F12: 21.627467
... A43: ZARZAL | B43: 2.3288309 | C43: 16.301816 | D43: 27.945971 | E43: 16.301816 | F43: 32.603633

Sheet Amenazas
A1: cole_mcpio_ubicacion | B1: 2020 | C1: 2021 | D1: 2022 | E1: 2023 | F1: 2024
A2: CALI | B2: 108.99173 | C2: 183.91806 | D2: 203.64706 | E2: 142.44334 | F2: 104.47598
A3: ALCALA | B3: 303.30818 | C3: 162.23461 | D3: 112.85886 | E3: 77.590463 | F3: 42.322071
A4: ANDALUCIA | B4: 113.6463 | C4: 83.049218 | D4: 152.9854 | E4: 83.049218 | F4: 131.13034
A5: ANSERMANUEVO | B5: 68.442366 | C5: 102.66355 | D5: 85.552957 | E5: 34.221183 | F5: 62.738835
A6: ARGELIA | B6: 19.076688 | C6: 0 | D6: 38.153377 | E6: 0 | F6: 38.153377
A7: BOLIVAR | B7: 69.134561 | C7: 25.13984 | D7: 150.83904 | E7: 207.40368 | F7: 119.41424
A8: BUENAVENTURA | B8: 66.826501 | C8: 161.52377 | D8: 250.20349 | E8: 162.79062 | F8: 121.6179
A9: GUADALAJARA DE BUGA | B9: 99.568028 | C9: 114.88619 | D9: 101.09984 | E9: 98.80212 | F9: 114.12028
A10: BUGALAGRANDE | B10: 149.36218 | C10: 153.399 | D10: 262.39302 | E10: 234.13531 | F10: 185.69352
A11: CAICEDONIA | B11: 58.866304 | C11: 41.552685 | D11: 110.80716 | E11: 96.956266 | F11: 96.956266
A12: CALIMA EL DARIEN | B12: 113.5442 | C12: 54.068667 | D12: 48.6618 | E12: 178.4266 | F12: 102.73047
... A43: ZARZAL | B43: 95.482068 | C43: 83.837913 | D43: 179.31998 | E43: 128.0857 | F43: 221.23894

Sheet Hurtos
A1: cole_mcpio_ubicacion | B1: 2020 | C1: 2021 | D1: 2022 | E1: 2023 | F1: 2024
A2: CALI | B2: 1010.7821 | C2: 1267.5659 | D2: 1451.8786 | E2: 1375.1109 | F2: 1300.4476
A3: ALCALA | B3: 338.57657 | C3: 451.43542 | D3: 451.43542 | E3: 303.30818 | F3: 387.95232
A4: ANDALUCIA | B4: 192.3245 | C4: 244.77664 | D4: 275.37372 | E4: 253.51866 | F4: 187.95349
A5: ANSERMANUEVO | B5: 125.47767 | C5: 176.80945 | D5: 233.84475 | E5: 216.73416 | F5: 176.80945
A6: ARGELIA | B6: 95.383441 | C6: 133.53682 | D6: 38.153377 | E6: 114.46013 | F6: 76.306753
A7: BOLIVAR | B7: 56.564641 | C7: 87.989441 | D7: 188.5488 | E7: 138.26912 | F7: 119.41424
A8: BUENAVENTURA | B8: 322.73083 | C8: 402.54257 | D8: 363.58684 | E8: 378.47237 | F8: 296.12691
A9: GUADALAJARA DE BUGA | B9: 328.57449 | C9: 431.20615 | D9: 628.04448 | E9: 603.53543 | F9: 543.02871
A10: BUGALAGRANDE | B10: 177.61989 | C10: 335.05571 | D10: 387.53431 | E10: 331.01889 | F10: 322.94526
A11: CAICEDONIA | B11: 214.68887 | C11: 301.25697 | D11: 394.75051 | E11: 367.04872 | F11: 294.33152
A12: CALIMA EL DARIEN | B12: 281.15707 | C12: 464.99054 | D12: 616.38281 | E12: 567.72101 | F12: 421.7356
... A43: ZARZAL | B43: 153.70284 | C43: 249.18491 | D43: 349.32464 | E43: 319.04984 | F43: 281.78854

Sheet Secuestro
A1: cole_mcpio_ubicacion | B1: 2020 | C1: 2021 | D1: 2022 | E1: 2023 | F1: 2024
A2: CALI | B2: 0.43842208 | C2: 0.43842208 | D2: 0.56994871 | E2: 0.92068638 | F2: 0.48226429 | H2: =MAX(B2:D43) -> 8.0736315
A3: ALCALA | B3: 0 | C3: 0 | D3: 0 | E3: 0 | F3: 0
A4: ANDALUCIA | B4: 0 | C4: 4.3710115 | D4: 0 | E4: 0 | F4: 0
A5: ANSERMANUEVO | B5: 5.7035305 | C5: 0 | D5: 0 | E5: 0 | F5: 0
A6: ARGELIA | B6: 0 | C6: 0 | D6: 0 | E6: 0 | F6: 0
A7: BOLIVAR | B7: 0 | C7: 0 | D7: 0 | E7: 0 | F7: 0
A8: BUENAVENTURA | B8: 1.9002797 | C8: 2.5337062 | D8: 2.2169929 | E8: 2.2169929 | F8: 0
A9: GUADALAJARA DE BUGA | B9: 0 | C9: 0 | D9: 0 | E9: 0 | F9: 0
A10: BUGALAGRANDE | B10: 0 | C10: 8.0736315 | D10: 0 | E10: 0 | F10: 8.0736315
A11: CAICEDONIA | B11: 0 | C11: 0 | D11: 0 | E11: 0 | F11: 0
A12: CALIMA EL DARIEN | B12: 0 | C12: 0 | D12: 0 | E12: 0 | F12: 0
A13: CANDELARIA | B13: 2.0961504 | C13: 0 | D13: 0 | E13: 2.0961504 | F13: 1.0480752
A14: CARTAGO | B14: 0 | C14: 0 | D14: 0.71928992 | E14: 0 | F14: 0.71928992
... A43: ZARZAL | B43: 0 | C43: 0 | D43: 0 | E43: 0 | F43: 0

Sheet Todos los Datos
B1: Indice Promedio Homicidios | C1: Indice Homicidios 2020 | D1: Indice Homicidios 2021 | E1: Indice Homicidios 2022 | F1: Indice Homicidios 2023 | G1: Indice Homicidios 2024 | H1: Indice Promedio Lesiones Personales | I1: Indice Lesiones Personales 2020 | J1: Indice Lesiones Personales 2021 | K1: Indice Lesiones Personales 2022 | L1: Indice Lesiones Personales 2023 | M1: Indice Lesiones Personales 2024 | N1: Indice Promedio Violencia Intrafamiliar | O1: Indice Violencia Intrafamiliar 2020 | P1: Indice Violencia Intrafamiliar 2021 | Q1: Indice Violencia Intrafamiliar 2022 | R1: Indice Violencia Intrafamiliar 2023 | S1: Indice Violencia Intrafamiliar 2024 | T1: Indice Promedio Delitos Sexuales | U1: Indice Delitos Sexuales 2020 | V1: Indice Delitos Sexuales 2021 | W1: Indice Delitos Sexuales 2022 | X1: Indice Delitos Sexuales 2023 | Y1: Indice Delitos Sexuales 2024 | Z1: Indice Promedio Extorsión | AA1: Indice Extorsión 2020 | AB1: Indice Extorsión 2021 | AC1: Indice Extorsión 2022 | AD1: Indice Extorsión 2023 | AE1: Indice Extorsión 2024 | AF1: Indice Promedio Amenazas | AG1: Indice Amenazas 2020 | AH1: Indice Amenazas 2021 | AI1: Indice Amenazas 2022 | AJ1: Indice Amenazas 2023 | AK1: Indice Amenazas 2024 | AL1: Indice Promedio Hurtos | AM1: Indice Hurtos 2020 | AN1: Indice Hurtos 2021 | AO1: Indice Hurtos 2022 | AP1: Indice Hurtos 2023 | AQ1: Indice Hurtos 2024 | AR1: Indice Promedio Secuestro | AS1: Indice Secuestro 2020 | AT1: Indice Secuestro 2021 | AU1: Indice Secuestro 2022 | AV1: Indice Secuestro 2023 | AW1: Indice Secuestro 2024
A2: CALI | B2: =AVERAGE(C2:G2) -> 45.674813 | C2: 46.735794 | D2: 52.698334 | E2: 43.228417 | F2: 44.061419 | G2: 41.650098 | H2: =AVERAGE(I2:M2) -> 201.26204 | I2: 206.27759 | J2: 214.16919 | K2: 181.24369 | L2: 201.93721 | M2: 202.68253 | N2: =AVERAGE(O2:S2) -> 246.70888 | O2: 225.48048 | P2: 255.46855 | Q2: 236.79177 | R2: 231.09228 | S2: 284.7113 | T2: =AVERAGE(U2:Y2) -> 53.733011 | U2: 60.15151 | V2: 63.395833 | W2: 44.587526 | X2: 51.032331 | Y2: 49.497853 | Z2: =AVERAGE(AA2:AE2) -> 21.517756 | AA2: 26.086114 | AB2: 24.858532 | AC2: 15.388615 | AD2: 20.518154 | AE2: 20.737365 | AF2: =AVERAGE(AG2:AK2) -> 148.69523 | AG2: 108.99173 | AH2: 183.91806 | AI2: 203.64706 | AJ2: 142.44334 | AK2: 104.47598 | AL2: =AVERAGE(AM2:AQ2) -> 1281.157 | AM2: 1010.7821 | AN2: 1267.5659 | AO2: 1451.8786 | AP2: 1375.1109 | AQ2: 1300.4476 | AR2: =AVERAGE(AS2:AW2) -> 0.56994871 | AS2: 0.43842208 | AT2: 0.43842208 | AU2: 0.56994871 | AV2: 0.92068638 | AW2: 0.48226429
A3: ALCALA | B3: =AVERAGE(C3:G3) -> 105.80518 | C3: 77.590463 | D3: 91.69782 | E3: 105.80518 | F3: 134.01989 | G3: 119.91253 | H3: =AVERAGE(I3:M3) -> 193.27079 | I3: 183.39564 | J3: 162.23461 | K3: 225.71771 | L3: 176.34196 | M3: 218.66403 | N3: =AVERAGE(O3:S3) -> 187.62785 | O3: 204.55668 | P3: 183.39564 | Q3: 119.91253 | R3: 141.07357 | S3: 289.20082 | T3: =AVERAGE(U3:Y3) -> 83.233406 | U3: 63.483106 | V3: 70.536785 | W3: 35.268392 | X3: 70.536785 | Y3: 176.34196 | Z3: =AVERAGE(AA3:AE3) -> 14.107357 | AA3: 14.107357 | AB3: 7.0536785 | AC3: 28.214714 | AD3: 21.161035 | AE3: 0 | AF3: =AVERAGE(AG3:AK3) -> 139.66283 | AG3: 303.30818 | AH3: 162.23461 | AI3: 112.85886 | AJ3: 77.590463 | AK3: 42.322071 | AL3: =AVERAGE(AM3:AQ3) -> 386.54158 | AM3: 338.57657 | AN3: 451.43542 | AO3: 451.43542 | AP3: 303.30818 | AQ3: 387.95232 | AR3: =AVERAGE(AS3:AW3) -> 0 | AS3: 0 | AT3: 0 | AU3: 0 | AV3: 0 | AW3: 0
A4: ANDALUCIA | B4: =AVERAGE(C4:G4) -> 55.074744 | C4: 48.081126 | D4: 65.565172 | E4: 39.339103 | F4: 61.19416 | G4: 61.19416 | H4: =AVERAGE(I4:M4) -> 112.7721 | I4: 100.53326 | J4: 100.53326 | K4: 170.46945 | L4: 118.01731 | M4: 74.307195 | N4: =AVERAGE(O4:S4) -> 209.80855 | O4: 113.6463 | P4: 218.55057 | Q4: 157.35641 | R4: 310.34181 | S4: 249.14765 | T4: =AVERAGE(U4:Y4) -> 65.565172 | U4: 61.19416 | V4: 74.307195 | W4: 65.565172 | X4: 87.420229 | Y4: 39.339103 | Z4: =AVERAGE(AA4:AE4) -> 20.106653 | AA4: 39.339103 | AB4: 4.3710115 | AC4: 13.113034 | AD4: 17.484046 | AE4: 26.226069 | AF4: =AVERAGE(AG4:AK4) -> 112.7721 | AG4: 113.6463 | AH4: 83.049218 | AI4: 152.9854 | AJ4: 83.049218 | AK4: 131.13034 | AL4: =AVERAGE(AM4:AQ4) -> 230.7894 | AM4: 192.3245 | AN4: 244.77664 | AO4: 275.37372 | AP4: 253.51866 | AQ4: 187.95349 | AR4: =AVERAGE(AS4:AW4) -> 0.87420229 | AS4: 0 | AT4: 4.3710115 | AU4: 0 | AV4: 0 | AW4: 0
A5: ANSERMANUEVO | B5: =AVERAGE(C5:G5) -> 167.6838 | C5: 74.145896 | D5: 68.442366 | E5: 205.3271 | F5: 245.25181 | G5: 245.25181 | H5: =AVERAGE(I5:M5) -> 132.32191 | I5: 85.552957 | J5: 91.256488 | K5: 193.92004 | L5: 131.1812 | M5: 159.69885 | N5: =AVERAGE(O5:S5) -> 69.583072 | O5: 28.517652 | P5: 68.442366 | Q5: 91.256488 | R5: 91.256488 | S5: 68.442366 | T5: =AVERAGE(U5:Y5) -> 35.361889 | U5: 51.331774 | V5: 22.814122 | W5: 17.110591 | X5: 51.331774 | Y5: 34.221183 | Z5: =AVERAGE(AA5:AE5) -> 14.829179 | AA5: 17.110591 | AB5: 0 | AC5: 28.517652 | AD5: 11.407061 | AE5: 17.110591 | AF5: =AVERAGE(AG5:AK5) -> 70.723778 | AG5: 68.442366 | AH5: 102.66355 | AI5: 85.552957 | AJ5: 34.221183 | AK5: 62.738835 | AL5: =AVERAGE(AM5:AQ5) -> 185.93509 | AM5: 125.47767 | AN5: 176.80945 | AO5: 233.84475 | AP5: 216.73416 | AQ5: 176.80945 | AR5: =AVERAGE(AS5:AW5) -> 1.1407061 | AS5: 5.7035305 | AT5: 0 | AU5: 0 | AV5: 0 | AW5: 0
A6: ARGELIA | B6: =AVERAGE(C6:G6) -> 45.784052 | C6: 38.153377 | D6: 19.076688 | E6: 0 | F6: 76.306753 | G6: 95.383441 | H6: =AVERAGE(I6:M6) -> 118.27547 | I6: 57.230065 | J6: 95.383441 | K6: 152.61351 | L6: 152.61351 | M6: 133.53682 | N6: =AVERAGE(O6:S6) -> 141.16749 | O6: 190.76688 | P6: 305.22701 | Q6: 114.46013 | R6: 19.076688 | S6: 76.306753 | T6: =AVERAGE(U6:Y6) -> 53.414727 | U6: 38.153377 | V6: 114.46013 | W6: 19.076688 | X6: 57.230065 | Y6: 38.153377 | Z6: =AVERAGE(AA6:AE6) -> 11.446013 | AA6: 19.076688 | AB6: 0 | AC6: 0 | AD6: 19.076688 | AE6: 19.076688 | AF6: =AVERAGE(AG6:AK6) -> 19.076688 | AG6: 19.076688 | AH6: 0 | AI6: 38.153377 | AJ6: 0 | AK6: 38.153377 | AL6: =AVERAGE(AM6:AQ6) -> 91.568104 | AM6: 95.383441 | AN6: 133.53682 | AO6: 38.153377 | AP6: 114.46013 | AQ6: 76.306753 | AR6: =AVERAGE(AS6:AW6) -> 0 | AS6: 0 | AT6: 0 | AU6: 0 | AV6: 0 | AW6: 0
A7: BOLIVAR | B7: =AVERAGE(C7:G7) -> 61.592609 | C7: 50.279681 | D7: 37.709761 | E7: 31.4248 | F7: 31.4248 | G7: 157.124 | H7: =AVERAGE(I7:M7) -> 164.66595 | I7: 100.55936 | J7: 157.124 | K7: 169.69392 | L7: 226.25856 | M7: 169.69392 | N7: =AVERAGE(O7:S7) -> 173.4649 | O7: 106.84432 | P7: 119.41424 | Q7: 182.26384 | R7: 270.25328 | S7: 188.5488 | T7: =AVERAGE(U7:Y7) -> 56.564641 | U7: 75.419521 | V7: 69.134561 | W7: 43.994721 | X7: 56.564641 | Y7: 37.709761 | Z7: =AVERAGE(AA7:AE7) -> 8.7989441 | AA7: 6.2849601 | AB7: 0 | AC7: 0 | AD7: 6.2849601 | AE7: 31.4248 | AF7: =AVERAGE(AG7:AK7) -> 114.38627 | AG7: 69.134561 | AH7: 25.13984 | AI7: 150.83904 | AJ7: 207.40368 | AK7: 119.41424 | AL7: =AVERAGE(AM7:AQ7) -> 118.15725 | AM7: 56.564641 | AN7: 87.989441 | AO7: 188.5488 | AP7: 138.26912 | AQ7: 119.41424 | AR7: =AVERAGE(AS7:AW7) -> 0 | AS7: 0 | AT7: 0 | AU7: 0 | AV7: 0 | AW7: 0
A8: BUENAVENTURA | B8: =AVERAGE(C8:G8) -> 39.779188 | C8: 35.155174 | D8: 61.125662 | E8: 34.521747 | F8: 43.073006 | G8: 25.020349 | H8: =AVERAGE(I8:M8) -> 100.01805 | I8: 83.295592 | J8: 123.20146 | K8: 102.6151 | L8: 118.76748 | M8: 72.210627 | N8: =AVERAGE(O8:S8) -> 79.43169 | O8: 99.131255 | P8: 75.37776 | Q8: 63.025942 | R8: 73.160767 | S8: 86.462724 | T8: =AVERAGE(U8:Y8) -> 35.281859 | U8: 38.322306 | V8: 33.571607 | W8: 32.938181 | X8: 36.105313 | Y8: 35.471887 | Z8: =AVERAGE(AA8:AE8) -> 57.831844 | AA8: 31.988041 | AB8: 76.011186 | AC8: 81.395312 | AD8: 50.040698 | AE8: 49.723984 | AF8: =AVERAGE(AG8:AK8) -> 152.59246 | AG8: 66.826501 | AH8: 161.52377 | AI8: 250.20349 | AJ8: 162.79062 | AK8: 121.6179 | AL8: =AVERAGE(AM8:AQ8) -> 352.6919 | AM8: 322.73083 | AN8: 402.54257 | AO8: 363.58684 | AP8: 378.47237 | AQ8: 296.12691 | AR8: =AVERAGE(AS8:AW8) -> 1.7735943 | AS8: 1.9002797 | AT8: 2.5337062 | AU8: 2.2169929 | AV8: 2.2169929 | AW8: 0
A9: GUADALAJARA DE BUGA | B9: =AVERAGE(C9:G9) -> 58.821727 | C9: 45.954474 | D9: 58.209001 | E9: 68.165804 | F9: 56.677185 | G9: 65.102172 | H9: =AVERAGE(I9:M9) -> 263.77868 | I9: 240.49508 | J9: 235.13373 | K9: 251.9837 | L9: 314.02224 | M9: 277.25866 | N9: =AVERAGE(O9:S9) -> 291.65773 | O9: 250.45189 | P9: 295.64045 | Q9: 267.30186 | R9: 308.66089 | S9: 336.23357 | T9: =AVERAGE(U9:Y9) -> 54.685825 | U9: 52.847646 | V9: 54.379461 | W9: 45.188567 | X9: 56.677185 | Y9: 64.336264 | Z9: =AVERAGE(AA9:AE9) -> 20.679513 | AA9: 22.211329 | AB9: 11.488619 | AC9: 19.913606 | AD9: 16.849974 | AE9: 32.93404 | AF9: =AVERAGE(AG9:AK9) -> 105.69529 | AG9: 99.568028 | AH9: 114.88619 | AI9: 101.09984 | AJ9: 98.80212 | AK9: 114.12028 | AL9: =AVERAGE(AM9:AQ9) -> 506.87785 | AM9: 328.57449 | AN9: 431.20615 | AO9: 628.04448 | AP9: 603.53543 | AQ9: 543.02871 | AR9: =AVERAGE(AS9:AW9) -> 0 | AS9: 0 | AT9: 0 | AU9: 0 | AV9: 0 | AW9: 0
A10: BUGALAGRANDE | B10: =AVERAGE(C10:G10) -> 59.744873 | C10: 64.589052 | D10: 44.404973 | E10: 48.441789 | F10: 92.846762 | G10: 48.441789 | H10: =AVERAGE(I10:M10) -> 191.34507 | I10: 193.76716 | J10: 129.1781 | K10: 278.54029 | L10: 169.54626 | M10: 185.69352 | N10: =AVERAGE(O10:S10) -> 141.28855 | O10: 92.846762 | P10: 149.36218 | Q10: 121.10447 | R10: 141.28855 | S10: 201.84079 | T10: =AVERAGE(U10:Y10) -> 56.515421 | U10: 56.515421 | V10: 44.404973 | W10: 52.478605 | X10: 68.625868 | Y10: 60.552236 | Z10: =AVERAGE(AA10:AE10) -> 25.028258 | AA10: 32.294526 | AB10: 8.0736315 | AC10: 20.184079 | AD10: 24.220895 | AE10: 40.368158 | AF10: =AVERAGE(AG10:AK10) -> 196.99661 | AG10: 149.36218 | AH10: 153.399 | AI10: 262.39302 | AJ10: 234.13531 | AK10: 185.69352 | AL10: =AVERAGE(AM10:AQ10) -> 310.83481 | AM10: 177.61989 | AN10: 335.05571 | AO10: 387.53431 | AP10: 331.01889 | AQ10: 322.94526 | AR10: =AVERAGE(AS10:AW10) -> 3.2294526 | AS10: 0 | AT10: 8.0736315 | AU10: 0 | AV10: 0 | AW10: 8.0736315
A11: CAICEDONIA | B11: =AVERAGE(C11:G11) -> 63.021573 | C11: 58.866304 | D11: 62.329028 | E11: 55.40358 | F11: 83.105371 | G11: 55.40358 | H11: =AVERAGE(I11:M11) -> 263.16701 | I11: 221.61432 | J11: 238.92794 | K11: 349.7351 | L11: 252.77884 | M11: 252.77884 | N11: =AVERAGE(O11:S11) -> 144.74185 | O11: 197.37526 | P11: 114.26988 | Q11: 128.12078 | R11: 128.12078 | S11: 155.82257 | T11: =AVERAGE(U11:Y11) -> 40.860141 | U11: 51.940857 | V11: 76.179923 | W11: 38.089962 | X11: 13.850895 | Y11: 24.239066 | Z11: =AVERAGE(AA11:AE11) -> 9.0030818 | AA11: 13.850895 | AB11: 6.9254476 | AC11: 10.388171 | AD11: 6.9254476 | AE11: 6.9254476 | AF11: =AVERAGE(AG11:AK11) -> 81.027736 | AG11: 58.866304 | AH11: 41.552685 | AI11: 110.80716 | AJ11: 96.956266 | AK11: 96.956266 | AL11: =AVERAGE(AM11:AQ11) -> 314.41532 | AM11: 214.68887 | AN11: 301.25697 | AO11: 394.75051 | AP11: 367.04872 | AQ11: 294.33152 | AR11: =AVERAGE(AS11:AW11) -> 0 | AS11: 0 | AT11: 0 | AU11: 0 | AV11: 0 | AW11: 0
A12: CALIMA EL DARIEN | B12: =AVERAGE(C12:G12) -> 32.4412 | C12: 32.4412 | D12: 43.254934 | E12: 27.034334 | F12: 32.4412 | G12: 27.034334 | H12: =AVERAGE(I12:M12) -> 232.49527 | I12: 162.206 | J12: 216.27467 | K12: 243.309 | L12: 286.56394 | M12: 254.12274 | N12: =AVERAGE(O12:S12) -> 177.34523 | O12: 118.95107 | P12: 189.24034 | Q12: 162.206 | R12: 178.4266 | S12: 237.90214 | T12: =AVERAGE(U12:Y12) -> 63.801027 | U12: 75.696134 | V12: 59.475534 | W12: 75.696134 | X12: 37.848067 | Y12: 70.289267 | Z12: =AVERAGE(AA12:AE12) -> 19.46472 | AA12: 27.034334 | AB12: 0 | AC12: 21.627467 | AD12: 27.034334 | AE12: 21.627467 | AF12: =AVERAGE(AG12:AK12) -> 99.486348 | AG12: 113.5442 | AH12: 54.068667 | AI12: 48.6618 | AJ12: 178.4266 | AK12: 102.73047 | AL12: =AVERAGE(AM12:AQ12) -> 470.3974 | AM12: 281.15707 | AN12: 464.99054 | AO12: 616.38281 | AP12: 567.72101 | AQ12: 421.7356 | AR12: =AVERAGE(AS12:AW12) -> 0 | AS12: 0 | AT12: 0 | AU12: 0 | AV12: 0 | AW12: 0
A13: CANDELARIA | B13: =AVERAGE(C13:G13) -> 64.980663 | C13: 80.701791 | D13: 60.788362 | E13: 68.124889 | F13: 55.547986 | G13: 59.740287 | H13: =AVERAGE(I13:M13) -> 248.60344 | I13: 158.25936 | J13: 200.18237 | K13: 310.23026 | L13: 313.37449 | M13: 260.97073 | N13: =AVERAGE(O13:S13) -> 281.30339 | O13: 253.6342 | P13: 322.80716 | Q13: 278.78801 | R13: 274.5957 | S13: 276.69186 | T13: =AVERAGE(U13:Y13) -> 65.399893 | U13: 48.21146 | V13: 77.557566 | W13: 59.740287 | X13: 62.884513 | Y13: 78.605641 | Z13: =AVERAGE(AA13:AE13) -> 16.140358 | AA13: 14.673053 | AB13: 13.624978 | AC13: 17.817279 | AD13: 15.721128 | AE13: 18.865354 | AF13: =AVERAGE(AG13:AK13) -> 151.13245 | AG13: 113.19212 | AH13: 164.54781 | AI13: 136.24978 | AJ13: 163.49973 | AK13: 178.17279 | AL13: =AVERAGE(AM13:AQ13) -> 721.07574 | AM13: 520.89338 | AN13: 638.2778 | AO13: 800.72946 | AP13: 768.23913 | AQ13: 877.23895 | AR13: =AVERAGE(AS13:AW13) -> 1.0480752 | AS13: 2.0961504 | AT13: 0 | AU13: 0 | AV13: 2.0961504 | AW13: 1.0480752
... A43: ZARZAL | B43: =AVERAGE(C43:G43) -> 63.809967 | C43: 58.220773 | D43: 60.549604 | E43: 53.563111 | F43: 60.549604 | G43: 86.166744 | H43: =AVERAGE(I43:M43) -> 234.74616 | I43: 167.67583 | J43: 274.80205 | K43: 284.11737 | L43: 207.26595 | M43: 239.86959 | N43: =AVERAGE(O43:S43) -> 225.8966 | O43: 223.56777 | P43: 302.74802 | Q43: 209.59478 | R43: 170.00466 | S43: 223.56777 | T43: =AVERAGE(U43:Y43) -> 43.316255 | U43: 48.905449 | V43: 60.549604 | W43: 34.932464 | X43: 30.274802 | Y43: 41.918957 | Z43: =AVERAGE(AA43:AE43) -> 19.096414 | AA43: 2.3288309 | AB43: 16.301816 | AC43: 27.945971 | AD43: 16.301816 | AE43: 32.603633 | AF43: =AVERAGE(AG43:AK43) -> 141.59292 | AG43: 95.482068 | AH43: 83.837913 | AI43: 179.31998 | AJ43: 128.0857 | AK43: 221.23894 | AL43: =AVERAGE(AM43:AQ43) -> 270.61015 | AM43: 153.70284 | AN43: 249.18491 | AO43: 349.32464 | AP43: 319.04984 | AQ43: 281.78854 | AR43: =AVERAGE(AS43:AW43) -> 0 | AS43: 0 | AT43: 0 | AU43: 0 | AV43: 0 | AW43: 0

Sheet Todos los Datos (2)
B1: Indice Homicidios 2020 | C1: Indice Homicidios 2021 | D1: Indice Homicidios 2022 | E1: Indice Homicidios 2023 | F1: Indice Homicidios 2024 | G1: Indice Lesiones Personales 2020 | H1: Indice Lesiones Personales 2021 | I1: Indice Lesiones Personales 2022 | J1: Indice Lesiones Personales 2023 | K1: Indice Lesiones Personales 2024 | L1: Indice Violencia Intrafamiliar 2020 | M1: Indice Violencia Intrafamiliar 2021 | N1: Indice Violencia Intrafamiliar 2022 | O1: Indice Violencia Intrafamiliar 2023 | P1: Indice Violencia Intrafamiliar 2024 | Q1: Indice Delitos Sexuales 2020 | R1: Indice Delitos Sexuales 2021 | S1: Indice Delitos Sexuales 2022 | T1: Indice Delitos Sexuales 2023 | U1: Indice Delitos Sexuales 2024 | V1: Indice Extorsión 2020 | W1: Indice Extorsión 2021 | X1: Indice Extorsión 2022 | Y1: Indice Extorsión 2023 | Z1: Indice Extorsión 2024 | AA1: Indice Amenazas 2020 | AB1: Indice Amenazas 2021 | AC1: Indice Amenazas 2022 | AD1: Indice Amenazas 2023 | AE1: Indice Amenazas 2024 | AF1: Indice Hurtos 2020 | AG1: Indice Hurtos 2021 | AH1: Indice Hurtos 2022 | AI1: Indice Hurtos 2023 | AJ1: Indice Hurtos 2024 | AK1: Indice Secuestro 2020 | AL1: Indice Secuestro 2021 | AM1: Indice Secuestro 2022 | AN1: Indice Secuestro 2023 | AO1: Indice Secuestro 2024
A2: CALI | B2: 46.735794 | C2: 52.698334 | D2: 43.228417 | E2: 44.061419 | F2: 41.650098 | G2: 206.27759 | H2: 214.16919 | I2: 181.24369 | J2: 201.93721 | K2: 202.68253 | L2: 225.48048 | M2: 255.46855 | N2: 236.79177 | O2: 231.09228 | P2: 284.7113 | Q2: 60.15151 | R2: 63.395833 | S2: 44.587526 | T2: 51.032331 | U2: 49.497853 | V2: 26.086114 | W2: 24.858532 | X2: 15.388615 | Y2: 20.518154 | Z2: 20.737365 | AA2: 108.99173 | AB2: 183.91806 | AC2: 203.64706 | AD2: 142.44334 | AE2: 104.47598 | AF2: 1010.7821 | AG2: 1267.5659 | AH2: 1451.8786 | AI2: 1375.1109 | AJ2: 1300.4476 | AK2: 0.43842208 | AL2: 0.43842208 | AM2: 0.56994871 | AN2: 0.92068638 | AO2: 0.48226429
A3: ALCALA | B3: 77.590463 | C3: 91.69782 | D3: 105.80518 | E3: 134.01989 | F3: 119.91253 | G3: 183.39564 | H3: 162.23461 | I3: 225.71771 | J3: 176.34196 | K3: 218.66403 | L3: 204.55668 | M3: 183.39564 | N3: 119.91253 | O3: 141.07357 | P3: 289.20082 | Q3: 63.483106 | R3: 70.536785 | S3: 35.268392 | T3: 70.536785 | U3: 176.34196 | V3: 14.107357 | W3: 7.0536785 | X3: 28.214714 | Y3: 21.161035 | Z3: 0 | AA3: 303.30818 | AB3: 162.23461 | AC3: 112.85886 | AD3: 77.590463 | AE3: 42.322071 | AF3: 338.57657 | AG3: 451.43542 | AH3: 451.43542 | AI3: 303.30818 | AJ3: 387.95232 | AK3: 0 | AL3: 0 | AM3: 0 | AN3: 0 | AO3: 0
A4: ANDALUCIA | B4: 48.081126 | C4: 65.565172 | D4: 39.339103 | E4: 61.19416 | F4: 61.19416 | G4: 100.53326 | H4: 100.53326 | I4: 170.46945 | J4: 118.01731 | K4: 74.307195 | L4: 113.6463 | M4: 218.55057 | N4: 157.35641 | O4: 310.34181 | P4: 249.14765 | Q4: 61.19416 | R4: 74.307195 | S4: 65.565172 | T4: 87.420229 | U4: 39.339103 | V4: 39.339103 | W4: 4.3710115 | X4: 13.113034 | Y4: 17.484046 | Z4: 26.226069 | AA4: 113.6463 | AB4: 83.049218 | AC4: 152.9854 | AD4: 83.049218 | AE4: 131.13034 | AF4: 192.3245 | AG4: 244.77664 | AH4: 275.37372 | AI4: 253.51866 | AJ4: 187.95349 | AK4: 0 | AL4: 4.3710115 | AM4: 0 | AN4: 0 | AO4: 0
A5: ANSERMANUEVO | B5: 74.145896 | C5: 68.442366 | D5: 205.3271 | E5: 245.25181 | F5: 245.25181 | G5: 85.552957 | H5: 91.256488 | I5: 193.92004 | J5: 131.1812 | K5: 159.69885 | L5: 28.517652 | M5: 68.442366 | N5: 91.256488 | O5: 91.256488 | P5: 68.442366 | Q5: 51.331774 | R5: 22.814122 | S5: 17.110591 | T5: 51.331774 | U5: 34.221183 | V5: 17.110591 | W5: 0 | X5: 28.517652 | Y5: 11.407061 | Z5: 17.110591 | AA5: 68.442366 | AB5: 102.66355 | AC5: 85.552957 | AD5: 34.221183 | AE5: 62.738835 | AF5: 125.47767 | AG5: 176.80945 | AH5: 233.84475 | AI5: 216.73416 | AJ5: 176.80945 | AK5: 5.7035305 | AL5: 0 | AM5: 0 | AN5: 0 | AO5: 0
A6: ARGELIA | B6: 38.153377 | C6: 19.076688 | D6: 0 | E6: 76.306753 | F6: 95.383441 | G6: 57.230065 | H6: 95.383441 | I6: 152.61351 | J6: 152.61351 | K6: 133.53682 | L6: 190.76688 | M6: 305.22701 | N6: 114.46013 | O6: 19.076688 | P6: 76.306753 | Q6: 38.153377 | R6: 114.46013 | S6: 19.076688 | T6: 57.230065 | U6: 38.153377 | V6: 19.076688 | W6: 0 | X6: 0 | Y6: 19.076688 | Z6: 19.076688 | AA6: 19.076688 | AB6: 0 | AC6: 38.153377 | AD6: 0 | AE6: 38.153377 | AF6: 95.383441 | AG6: 133.53682 | AH6: 38.153377 | AI6: 114.46013 | AJ6: 76.306753 | AK6: 0 | AL6: 0 | AM6: 0 | AN6: 0 | AO6: 0
A7: BOLIVAR | B7: 50.279681 | C7: 37.709761 | D7: 31.4248 | E7: 31.4248 | F7: 157.124 | G7: 100.55936 | H7: 157.124 | I7: 169.69392 | J7: 226.25856 | K7: 169.69392 | L7: 106.84432 | M7: 119.41424 | N7: 182.26384 | O7: 270.25328 | P7: 188.5488 | Q7: 75.419521 | R7: 69.134561 | S7: 43.994721 | T7: 56.564641 | U7: 37.709761 | V7: 6.2849601 | W7: 0 | X7: 0 | Y7: 6.2849601 | Z7: 31.4248 | AA7: 69.134561 | AB7: 25.13984 | AC7: 150.83904 | AD7: 207.40368 | AE7: 119.41424 | AF7: 56.564641 | AG7: 87.989441 | AH7: 188.5488 | AI7: 138.26912 | AJ7: 119.41424 | AK7: 0 | AL7: 0 | AM7: 0 | AN7: 0 | AO7: 0
A8: BUENAVENTURA | B8: 35.155174 | C8: 61.125662 | D8: 34.521747 | E8: 43.073006 | F8: 25.020349 | G8: 83.295592 | H8: 123.20146 | I8: 102.6151 | J8: 118.76748 | K8: 72.210627 | L8: 99.131255 | M8: 75.37776 | N8: 63.025942 | O8: 73.160767 | P8: 86.462724 | Q8: 38.322306 | R8: 33.571607 | S8: 32.938181 | T8: 36.105313 | U8: 35.471887 | V8: 31.988041 | W8: 76.011186 | X8: 81.395312 | Y8: 50.040698 | Z8: 49.723984 | AA8: 66.826501 | AB8: 161.52377 | AC8: 250.20349 | AD8: 162.79062 | AE8: 121.6179 | AF8: 322.73083 | AG8: 402.54257 | AH8: 363.58684 | AI8: 378.47237 | AJ8: 296.12691 | AK8: 1.9002797 | AL8: 2.5337062 | AM8: 2.2169929 | AN8: 2.2169929 | AO8: 0
A9: GUADALAJARA DE BUGA | B9: 45.954474 | C9: 58.209001 | D9: 68.165804 | E9: 56.677185 | F9: 65.102172 | G9: 240.49508 | H9: 235.13373 | I9: 251.9837 | J9: 314.02224 | K9: 277.25866 | L9: 250.45189 | M9: 295.64045 | N9: 267.30186 | O9: 308.66089 | P9: 336.23357 | Q9: 52.847646 | R9: 54.379461 | S9: 45.188567 | T9: 56.677185 | U9: 64.336264 | V9: 22.211329 | W9: 11.488619 | X9: 19.913606 | Y9: 16.849974 | Z9: 32.93404 | AA9: 99.568028 | AB9: 114.88619 | AC9: 101.09984 | AD9: 98.80212 | AE9: 114.12028 | AF9: 328.57449 | AG9: 431.20615 | AH9: 628.04448 | AI9: 603.53543 | AJ9: 543.02871 | AK9: 0 | AL9: 0 | AM9: 0 | AN9: 0 | AO9: 0
A10: BUGALAGRANDE | B10: 64.589052 | C10: 44.404973 | D10: 48.441789 | E10: 92.846762 | F10: 48.441789 | G10: 193.76716 | H10: 129.1781 | I10: 278.54029 | J10: 169.54626 | K10: 185.69352 | L10: 92.846762 | M10: 149.36218 | N10: 121.10447 | O10: 141.28855 | P10: 201.84079 | Q10: 56.515421 | R10: 44.404973 | S10: 52.478605 | T10: 68.625868 | U10: 60.552236 | V10: 32.294526 | W10: 8.0736315 | X10: 20.184079 | Y10: 24.220895 | Z10: 40.368158 | AA10: 149.36218 | AB10: 153.399 | AC10: 262.39302 | AD10: 234.13531 | AE10: 185.69352 | AF10: 177.61989 | AG10: 335.05571 | AH10: 387.53431 | AI10: 331.01889 | AJ10: 322.94526 | AK10: 0 | AL10: 8.0736315 | AM10: 0 | AN10: 0 | AO10: 8.0736315
A11: CAICEDONIA | B11: 58.866304 | C11: 62.329028 | D11: 55.40358 | E11: 83.105371 | F11: 55.40358 | G11: 221.61432 | H11: 238.92794 | I11: 349.7351 | J11: 252.77884 | K11: 252.77884 | L11: 197.37526 | M11: 114.26988 | N11: 128.12078 | O11: 128.12078 | P11: 155.82257 | Q11: 51.940857 | R11: 76.179923 | S11: 38.089962 | T11: 13.850895 | U11: 24.239066 | V11: 13.850895 | W11: 6.9254476 | X11: 10.388171 | Y11: 6.9254476 | Z11: 6.9254476 | AA11: 58.866304 | AB11: 41.552685 | AC11: 110.80716 | AD11: 96.956266 | AE11: 96.956266 | AF11: 214.68887 | AG11: 301.25697 | AH11: 394.75051 | AI11: 367.04872 | AJ11: 294.33152 | AK11: 0 | AL11: 0 | AM11: 0 | AN11: 0 | AO11: 0
A12: CALIMA EL DARIEN | B12: 32.4412 | C12: 43.254934 | D12: 27.034334 | E12: 32.4412 | F12: 27.034334 | G12: 162.206 | H12: 216.27467 | I12: 243.309 | J12: 286.56394 | K12: 254.12274 | L12: 118.95107 | M12: 189.24034 | N12: 162.206 | O12: 178.4266 | P12: 237.90214 | Q12: 75.696134 | R12: 59.475534 | S12: 75.696134 | T12: 37.848067 | U12: 70.289267 | V12: 27.034334 | W12: 0 | X12: 21.627467 | Y12: 27.034334 | Z12: 21.627467 | AA12: 113.5442 | AB12: 54.068667 | AC12: 48.6618 | AD12: 178.4266 | AE12: 102.73047 | AF12: 281.15707 | AG12: 464.99054 | AH12: 616.38281 | AI12: 567.72101 | AJ12: 421.7356 | AK12: 0 | AL12: 0 | AM12: 0 | AN12: 0 | AO12: 0
A13: CANDELARIA | B13: 80.701791 | C13: 60.788362 | D13: 68.124889 | E13: 55.547986 | F13: 59.740287 | G13: 158.25936 | H13: 200.18237 | I13: 310.23026 | J13: 313.37449 | K13: 260.97073 | L13: 253.6342 | M13: 322.80716 | N13: 278.78801 | O13: 274.5957 | P13: 276.69186 | Q13: 48.21146 | R13: 77.557566 | S13: 59.740287 | T13: 62.884513 | U13: 78.605641 | V13: 14.673053 | W13: 13.624978 | X13: 17.817279 | Y13: 15.721128 | Z13: 18.865354 | AA13: 113.19212 | AB13: 164.54781 | AC13: 136.24978 | AD13: 163.49973 | AE13: 178.17279 | AF13: 520.89338 | AG13: 638.2778 | AH13: 800.72946 | AI13: 768.23913 | AJ13: 877.23895 | AK13: 2.0961504 | AL13: 0 | AM13: 0 | AN13: 2.0961504 | AO13: 1.0480752
... A43: ZARZAL | B43: 58.220773 | C43: 60.549604 | D43: 53.563111 | E43: 60.549604 | F43: 86.166744 | G43: 167.67583 | H43: 274.80205 | I43: 284.11737 | J43: 207.26595 | K43: 239.86959 | L43: 223.56777 | M43: 302.74802 | N43: 209.59478 | O43: 170.00466 | P43: 223.56777 | Q43: 48.905449 | R43: 60.549604 | S43: 34.932464 | T43: 30.274802 | U43: 41.918957 | V43: 2.3288309 | W43: 16.301816 | X43: 27.945971 | Y43: 16.301816 | Z43: 32.603633 | AA43: 95.482068 | AB43: 83.837913 | AC43: 179.31998 | AD43: 128.0857 | AE43: 221.23894 | AF43: 153.70284 | AG43: 249.18491 | AH43: 349.32464 | AI43: 319.04984 | AJ43: 281.78854 | AK43: 0 | AL43: 0 | AM43: 0 | AN43: 0 | AO43: 0

Sheet Hoja1
B1: 2020 | C1: 2021 | D1: 2022 | E1: 2023 | F1: 2024
A2: CALI | B2: ='Todos los Datos (2)'!B2*Hoja1!$K$17+'Todos los Datos (2)'!G2*Hoja1!$K$18+'Todos los Datos (2)'!L2*Hoja1!$K$19+'Todos los Datos (2)'!Q2*Hoja1!$K$20+'Todos los Datos (2)'!V2*Hoja1!$K$21+'Todos los Datos (2)'!AA2*Hoja1!$K$22+'Todos los Datos (2)'!AF2*Hoja1!$K$23+'Todos los Datos (2)'!AK2*Hoja1!$K$24 -> 489.36604 | C2: ='Todos los Datos (2)'!C2*Hoja1!$K$17+'Todos los Datos (2)'!H2*Hoja1!$K$18+'Todos los Datos (2)'!M2*Hoja1!$K$19+'Todos los Datos (2)'!R2*Hoja1!$K$20+'Todos los Datos (2)'!W2*Hoja1!$K$21+'Todos los Datos (2)'!AB2*Hoja1!$K$22+'Todos los Datos (2)'!AG2*Hoja1!$K$23+'Todos los Datos (2)'!AL2*Hoja1!$K$24 -> 599.99712 | D2: ='Todos los Datos (2)'!D2*Hoja1!$K$17+'Todos los Datos (2)'!I2*Hoja1!$K$18+'Todos los Datos (2)'!N2*Hoja1!$K$19+'Todos los Datos (2)'!S2*Hoja1!$K$20+'Todos los Datos (2)'!X2*Hoja1!$K$21+'Todos los Datos (2)'!AC2*Hoja1!$K$22+'Todos los Datos (2)'!AH2*Hoja1!$K$23+'Todos los Datos (2)'!AM2*Hoja1!$K$24 -> 658.36706 | E2: ='Todos los Datos (2)'!E2*Hoja1!$K$17+'Todos los Datos (2)'!J2*Hoja1!$K$18+'Todos los Datos (2)'!O2*Hoja1!$K$19+'Todos los Datos (2)'!T2*Hoja1!$K$20+'Todos los Datos (2)'!Y2*Hoja1!$K$21+'Todos los Datos (2)'!AD2*Hoja1!$K$22+'Todos los Datos (2)'!AI2*Hoja1!$K$23+'Todos los Datos (2)'!AN2*Hoja1!$K$24 -> 627.77555 | F2: ='Todos los Datos (2)'!F2*Hoja1!$K$17+'Todos los Datos (2)'!K2*Hoja1!$K$18+'Todos los Datos (2)'!P2*Hoja1!$K$19+'Todos los Datos (2)'!U2*Hoja1!$K$20+'Todos los Datos (2)'!Z2*Hoja1!$K$21+'Todos los Datos (2)'!AE2*Hoja1!$K$22+'Todos los Datos (2)'!AJ2*Hoja1!$K$23+'Todos los Datos (2)'!AO2*Hoja1!$K$24 -> 621.90094
A3: ALCALA | B3: ='Todos los Datos (2)'!B3*Hoja1!$K$17+'Todos los Datos (2)'!G3*Hoja1!$K$18+'Todos los Datos (2)'!L3*Hoja1!$K$19+'Todos los Datos (2)'!Q3*Hoja1!$K$20+'Todos los Datos (2)'!V3*Hoja1!$K$21+'Todos los Datos (2)'!AA3*Hoja1!$K$22+'Todos los Datos (2)'!AF3*Hoja1!$K$23+'Todos los Datos (2)'!AK3*Hoja1!$K$24 -> 229.0348 | C3: ='Todos los Datos (2)'!C3*Hoja1!$K$17+'Todos los Datos (2)'!H3*Hoja1!$K$18+'Todos los Datos (2)'!M3*Hoja1!$K$19+'Todos los Datos (2)'!R3*Hoja1!$K$20+'Todos los Datos (2)'!W3*Hoja1!$K$21+'Todos los Datos (2)'!AB3*Hoja1!$K$22+'Todos los Datos (2)'!AG3*Hoja1!$K$23+'Todos los Datos (2)'!AL3*Hoja1!$K$24 -> 260.95522 | D3: ='Todos los Datos (2)'!D3*Hoja1!$K$17+'Todos los Datos (2)'!I3*Hoja1!$K$18+'Todos los Datos (2)'!N3*Hoja1!$K$19+'Todos los Datos (2)'!S3*Hoja1!$K$20+'Todos los Datos (2)'!X3*Hoja1!$K$21+'Todos los Datos (2)'!AC3*Hoja1!$K$22+'Todos los Datos (2)'!AH3*Hoja1!$K$23+'Todos los Datos (2)'!AM3*Hoja1!$K$24 -> 231.84047 | E3: ='Todos los Datos (2)'!E3*Hoja1!$K$17+'Todos los Datos (2)'!J3*Hoja1!$K$18+'Todos los Datos (2)'!O3*Hoja1!$K$19+'Todos los Datos (2)'!T3*Hoja1!$K$20+'Todos los Datos (2)'!Y3*Hoja1!$K$21+'Todos los Datos (2)'!AD3*Hoja1!$K$22+'Todos los Datos (2)'!AI3*Hoja1!$K$23+'Todos los Datos (2)'!AN3*Hoja1!$K$24 -> 187.39011 | F3: ='Todos los Datos (2)'!F3*Hoja1!$K$17+'Todos los Datos (2)'!K3*Hoja1!$K$18+'Todos los Datos (2)'!P3*Hoja1!$K$19+'Todos los Datos (2)'!U3*Hoja1!$K$20+'Todos los Datos (2)'!Z3*Hoja1!$K$21+'Todos los Datos (2)'!AE3*Hoja1!$K$22+'Todos los Datos (2)'!AJ3*Hoja1!$K$23+'Todos los Datos (2)'!AO3*Hoja1!$K$24 -> 293.24003
A4: ANDALUCIA | B4: ='Todos los Datos (2)'!B4*Hoja1!$K$17+'Todos los Datos (2)'!G4*Hoja1!$K$18+'Todos los Datos (2)'!L4*Hoja1!$K$19+'Todos los Datos (2)'!Q4*Hoja1!$K$20+'Todos los Datos (2)'!V4*Hoja1!$K$21+'Todos los Datos (2)'!AA4*Hoja1!$K$22+'Todos los Datos (2)'!AF4*Hoja1!$K$23+'Todos los Datos (2)'!AK4*Hoja1!$K$24 -> 132.88417 | C4: ='Todos los Datos (2)'!C4*Hoja1!$K$17+'Todos los Datos (2)'!H4*Hoja1!$K$18+'Todos los Datos (2)'!M4*Hoja1!$K$19+'Todos los Datos (2)'!R4*Hoja1!$K$20+'Todos los Datos (2)'!W4*Hoja1!$K$21+'Todos los Datos (2)'!AB4*Hoja1!$K$22+'Todos los Datos (2)'!AG4*Hoja1!$K$23+'Todos los Datos (2)'!AL4*Hoja1!$K$24 -> 196.37929 | D4: ='Todos los Datos (2)'!D4*Hoja1!$K$17+'Todos los Datos (2)'!I4*Hoja1!$K$18+'Todos los Datos (2)'!N4*Hoja1!$K$19+'Todos los Datos (2)'!S4*Hoja1!$K$20+'Todos los Datos (2)'!X4*Hoja1!$K$21+'Todos los Datos (2)'!AC4*Hoja1!$K$22+'Todos los Datos (2)'!AH4*Hoja1!$K$23+'Todos los Datos (2)'!AM4*Hoja1!$K$24 -> 183.43467 | E4: ='Todos los Datos (2)'!E4*Hoja1!$K$17+'Todos los Datos (2)'!J4*Hoja1!$K$18+'Todos los Datos (2)'!O4*Hoja1!$K$19+'Todos los Datos (2)'!T4*Hoja1!$K$20+'Todos los Datos (2)'!Y4*Hoja1!$K$21+'Todos los Datos (2)'!AD4*Hoja1!$K$22+'Todos los Datos (2)'!AI4*Hoja1!$K$23+'Todos los Datos (2)'!AN4*Hoja1!$K$24 -> 241.20209 | F4: ='Todos los Datos (2)'!F4*Hoja1!$K$17+'Todos los Datos (2)'!K4*Hoja1!$K$18+'Todos los Datos (2)'!P4*Hoja1!$K$19+'Todos los Datos (2)'!U4*Hoja1!$K$20+'Todos los Datos (2)'!Z4*Hoja1!$K$21+'Todos los Datos (2)'!AE4*Hoja1!$K$22+'Todos los Datos (2)'!AJ4*Hoja1!$K$23+'Todos los Datos (2)'!AO4*Hoja1!$K$24 -> 185.35654
A5: ANSERMANUEVO | B5: ='Todos los Datos (2)'!B5*Hoja1!$K$17+'Todos los Datos (2)'!G5*Hoja1!$K$18+'Todos los Datos (2)'!L5*Hoja1!$K$19+'Todos los Datos (2)'!Q5*Hoja1!$K$20+'Todos los Datos (2)'!V5*Hoja1!$K$21+'Todos los Datos (2)'!AA5*Hoja1!$K$22+'Todos los Datos (2)'!AF5*Hoja1!$K$23+'Todos los Datos (2)'!AK5*Hoja1!$K$24 -> 68.447361 | C5: ='Todos los Datos (2)'!C5*Hoja1!$K$17+'Todos los Datos (2)'!H5*Hoja1!$K$18+'Todos los Datos (2)'!M5*Hoja1!$K$19+'Todos los Datos (2)'!R5*Hoja1!$K$20+'Todos los Datos (2)'!W5*Hoja1!$K$21+'Todos los Datos (2)'!AB5*Hoja1!$K$22+'Todos los Datos (2)'!AG5*Hoja1!$K$23+'Todos los Datos (2)'!AL5*Hoja1!$K$24 -> 101.04396 | D5: ='Todos los Datos (2)'!D5*Hoja1!$K$17+'Todos los Datos (2)'!I5*Hoja1!$K$18+'Todos los Datos (2)'!N5*Hoja1!$K$19+'Todos los Datos (2)'!S5*Hoja1!$K$20+'Todos los Datos (2)'!X5*Hoja1!$K$21+'Todos los Datos (2)'!AC5*Hoja1!$K$22+'Todos los Datos (2)'!AH5*Hoja1!$K$23+'Todos los Datos (2)'!AM5*Hoja1!$K$24 -> 134.97895 | E5: ='Todos los Datos (2)'!E5*Hoja1!$K$17+'Todos los Datos (2)'!J5*Hoja1!$K$18+'Todos los Datos (2)'!O5*Hoja1!$K$19+'Todos los Datos (2)'!T5*Hoja1!$K$20+'Todos los Datos (2)'!Y5*Hoja1!$K$21+'Todos los Datos (2)'!AD5*Hoja1!$K$22+'Todos los Datos (2)'!AI5*Hoja1!$K$23+'Todos los Datos (2)'!AN5*Hoja1!$K$24 -> 129.73199 | F5: ='Todos los Datos (2)'!F5*Hoja1!$K$17+'Todos los Datos (2)'!K5*Hoja1!$K$18+'Todos los Datos (2)'!P5*Hoja1!$K$19+'Todos los Datos (2)'!U5*Hoja1!$K$20+'Todos los Datos (2)'!Z5*Hoja1!$K$21+'Todos los Datos (2)'!AE5*Hoja1!$K$22+'Todos los Datos (2)'!AJ5*Hoja1!$K$23+'Todos los Datos (2)'!AO5*Hoja1!$K$24 -> 104.25734
A6: ARGELIA | B6: ='Todos los Datos (2)'!B6*Hoja1!$K$17+'Todos los Datos (2)'!G6*Hoja1!$K$18+'Todos los Datos (2)'!L6*Hoja1!$K$19+'Todos los Datos (2)'!Q6*Hoja1!$K$20+'Todos los Datos (2)'!V6*Hoja1!$K$21+'Todos los Datos (2)'!AA6*Hoja1!$K$22+'Todos los Datos (2)'!AF6*Hoja1!$K$23+'Todos los Datos (2)'!AK6*Hoja1!$K$24 -> 123.60571 | C6: ='Todos los Datos (2)'!C6*Hoja1!$K$17+'Todos los Datos (2)'!H6*Hoja1!$K$18+'Todos los Datos (2)'!M6*Hoja1!$K$19+'Todos los Datos (2)'!R6*Hoja1!$K$20+'Todos los Datos (2)'!W6*Hoja1!$K$21+'Todos los Datos (2)'!AB6*Hoja1!$K$22+'Todos los Datos (2)'!AG6*Hoja1!$K$23+'Todos los Datos (2)'!AL6*Hoja1!$K$24 -> 194.56314 | D6: ='Todos los Datos (2)'!D6*Hoja1!$K$17+'Todos los Datos (2)'!I6*Hoja1!$K$18+'Todos los Datos (2)'!N6*Hoja1!$K$19+'Todos los Datos (2)'!S6*Hoja1!$K$20+'Todos los Datos (2)'!X6*Hoja1!$K$21+'Todos los Datos (2)'!AC6*Hoja1!$K$22+'Todos los Datos (2)'!AH6*Hoja1!$K$23+'Todos los Datos (2)'!AM6*Hoja1!$K$24 -> 68.363765 | E6: ='Todos los Datos (2)'!E6*Hoja1!$K$17+'Todos los Datos (2)'!J6*Hoja1!$K$18+'Todos los Datos (2)'!O6*Hoja1!$K$19+'Todos los Datos (2)'!T6*Hoja1!$K$20+'Todos los Datos (2)'!Y6*Hoja1!$K$21+'Todos los Datos (2)'!AD6*Hoja1!$K$22+'Todos los Datos (2)'!AI6*Hoja1!$K$23+'Todos los Datos (2)'!AN6*Hoja1!$K$24 -> 61.536606 | F6: ='Todos los Datos (2)'!F6*Hoja1!$K$17+'Todos los Datos (2)'!K6*Hoja1!$K$18+'Todos los Datos (2)'!P6*Hoja1!$K$19+'Todos los Datos (2)'!U6*Hoja1!$K$20+'Todos los Datos (2)'!Z6*Hoja1!$K$21+'Todos los Datos (2)'!AE6*Hoja1!$K$22+'Todos los Datos (2)'!AJ6*Hoja1!$K$23+'Todos los Datos (2)'!AO6*Hoja1!$K$24 -> 69.452141
A7: BOLIVAR | B7: ='Todos los Datos (2)'!B7*Hoja1!$K$17+'Todos los Datos (2)'!G7*Hoja1!$K$18+'Todos los Datos (2)'!L7*Hoja1!$K$19+'Todos los Datos (2)'!Q7*Hoja1!$K$20+'Todos los Datos (2)'!V7*Hoja1!$K$21+'Todos los Datos (2)'!AA7*Hoja1!$K$22+'Todos los Datos (2)'!AF7*Hoja1!$K$23+'Todos los Datos (2)'!AK7*Hoja1!$K$24 -> 78.162231 | C7: ='Todos los Datos (2)'!C7*Hoja1!$K$17+'Todos los Datos (2)'!H7*Hoja1!$K$18+'Todos los Datos (2)'!M7*Hoja1!$K$19+'Todos los Datos (2)'!R7*Hoja1!$K$20+'Todos los Datos (2)'!W7*Hoja1!$K$21+'Todos los Datos (2)'!AB7*Hoja1!$K$22+'Todos los Datos (2)'!AG7*Hoja1!$K$23+'Todos los Datos (2)'!AL7*Hoja1!$K$24 -> 94.807834 | D7: ='Todos los Datos (2)'!D7*Hoja1!$K$17+'Todos los Datos (2)'!I7*Hoja1!$K$18+'Todos los Datos (2)'!N7*Hoja1!$K$19+'Todos los Datos (2)'!S7*Hoja1!$K$20+'Todos los Datos (2)'!X7*Hoja1!$K$21+'Todos los Datos (2)'!AC7*Hoja1!$K$22+'Todos los Datos (2)'!AH7*Hoja1!$K$23+'Todos los Datos (2)'!AM7*Hoja1!$K$24 -> 158.15019 | E7: ='Todos los Datos (2)'!E7*Hoja1!$K$17+'Todos los Datos (2)'!J7*Hoja1!$K$18+'Todos los Datos (2)'!O7*Hoja1!$K$19+'Todos los Datos (2)'!T7*Hoja1!$K$20+'Todos los Datos (2)'!Y7*Hoja1!$K$21+'Todos los Datos (2)'!AD7*Hoja1!$K$22+'Todos los Datos (2)'!AI7*Hoja1!$K$23+'Todos los Datos (2)'!AN7*Hoja1!$K$24 -> 180.05673 | F7: ='Todos los Datos (2)'!F7*Hoja1!$K$17+'Todos los Datos (2)'!K7*Hoja1!$K$18+'Todos los Datos (2)'!P7*Hoja1!$K$19+'Todos los Datos (2)'!U7*Hoja1!$K$20+'Todos los Datos (2)'!Z7*Hoja1!$K$21+'Todos los Datos (2)'!AE7*Hoja1!$K$22+'Todos los Datos (2)'!AJ7*Hoja1!$K$23+'Todos los Datos (2)'!AO7*Hoja1!$K$24 -> 135.63503
A8: BUENAVENTURA | B8: ='Todos los Datos (2)'!B8*Hoja1!$K$17+'Todos los Datos (2)'!G8*Hoja1!$K$18+'Todos los Datos (2)'!L8*Hoja1!$K$19+'Todos los Datos (2)'!Q8*Hoja1!$K$20+'Todos los Datos (2)'!V8*Hoja1!$K$21+'Todos los Datos (2)'!AA8*Hoja1!$K$22+'Todos los Datos (2)'!AF8*Hoja1!$K$23+'Todos los Datos (2)'!AK8*Hoja1!$K$24 -> 171.9508 | C8: ='Todos los Datos (2)'!C8*Hoja1!$K$17+'Todos los Datos (2)'!H8*Hoja1!$K$18+'Todos los Datos (2)'!M8*Hoja1!$K$19+'Todos los Datos (2)'!R8*Hoja1!$K$20+'Todos los Datos (2)'!W8*Hoja1!$K$21+'Todos los Datos (2)'!AB8*Hoja1!$K$22+'Todos los Datos (2)'!AG8*Hoja1!$K$23+'Todos los Datos (2)'!AL8*Hoja1!$K$24 -> 195.63442 | D8: ='Todos los Datos (2)'!D8*Hoja1!$K$17+'Todos los Datos (2)'!I8*Hoja1!$K$18+'Todos los Datos (2)'!N8*Hoja1!$K$19+'Todos los Datos (2)'!S8*Hoja1!$K$20+'Todos los Datos (2)'!X8*Hoja1!$K$21+'Todos los Datos (2)'!AC8*Hoja1!$K$22+'Todos los Datos (2)'!AH8*Hoja1!$K$23+'Todos los Datos (2)'!AM8*Hoja1!$K$24 -> 176.5436 | E8: ='Todos los Datos (2)'!E8*Hoja1!$K$17+'Todos los Datos (2)'!J8*Hoja1!$K$18+'Todos los Datos (2)'!O8*Hoja1!$K$19+'Todos los Datos (2)'!T8*Hoja1!$K$20+'Todos los Datos (2)'!Y8*Hoja1!$K$21+'Todos los Datos (2)'!AD8*Hoja1!$K$22+'Todos los Datos (2)'!AI8*Hoja1!$K$23+'Todos los Datos (2)'!AN8*Hoja1!$K$24 -> 184.37683 | F8: ='Todos los Datos (2)'!F8*Hoja1!$K$17+'Todos los Datos (2)'!K8*Hoja1!$K$18+'Todos los Datos (2)'!P8*Hoja1!$K$19+'Todos los Datos (2)'!U8*Hoja1!$K$20+'Todos los Datos (2)'!Z8*Hoja1!$K$21+'Todos los Datos (2)'!AE8*Hoja1!$K$22+'Todos los Datos (2)'!AJ8*Hoja1!$K$23+'Todos los Datos (2)'!AO8*Hoja1!$K$24 -> 157.6312
A9: GUADALAJARA DE BUGA | B9: ='Todos los Datos (2)'!B9*Hoja1!$K$17+'Todos los Datos (2)'!G9*Hoja1!$K$18+'Todos los Datos (2)'!L9*Hoja1!$K$19+'Todos los Datos (2)'!Q9*Hoja1!$K$20+'Todos los Datos (2)'!V9*Hoja1!$K$21+'Todos los Datos (2)'!AA9*Hoja1!$K$22+'Todos los Datos (2)'!AF9*Hoja1!$K$23+'Todos los Datos (2)'!AK9*Hoja1!$K$24 -> 242.79618 | C9: ='Todos los Datos (2)'!C9*Hoja1!$K$17+'Todos los Datos (2)'!H9*Hoja1!$K$18+'Todos los Datos (2)'!M9*Hoja1!$K$19+'Todos los Datos (2)'!R9*Hoja1!$K$20+'Todos los Datos (2)'!W9*Hoja1!$K$21+'Todos los Datos (2)'!AB9*Hoja1!$K$22+'Todos los Datos (2)'!AG9*Hoja1!$K$23+'Todos los Datos (2)'!AL9*Hoja1!$K$24 -> 300.26414 | D9: ='Todos los Datos (2)'!D9*Hoja1!$K$17+'Todos los Datos (2)'!I9*Hoja1!$K$18+'Todos los Datos (2)'!N9*Hoja1!$K$19+'Todos los Datos (2)'!S9*Hoja1!$K$20+'Todos los Datos (2)'!X9*Hoja1!$K$21+'Todos los Datos (2)'!AC9*Hoja1!$K$22+'Todos los Datos (2)'!AH9*Hoja1!$K$23+'Todos los Datos (2)'!AM9*Hoja1!$K$24 -> 361.8858 | E9: ='Todos los Datos (2)'!E9*Hoja1!$K$17+'Todos los Datos (2)'!J9*Hoja1!$K$18+'Todos los Datos (2)'!O9*Hoja1!$K$19+'Todos los Datos (2)'!T9*Hoja1!$K$20+'Todos los Datos (2)'!Y9*Hoja1!$K$21+'Todos los Datos (2)'!AD9*Hoja1!$K$22+'Todos los Datos (2)'!AI9*Hoja1!$K$23+'Todos los Datos (2)'!AN9*Hoja1!$K$24 -> 372.46168 | F9: ='Todos los Datos (2)'!F9*Hoja1!$K$17+'Todos los Datos (2)'!K9*Hoja1!$K$18+'Todos los Datos (2)'!P9*Hoja1!$K$19+'Todos los Datos (2)'!U9*Hoja1!$K$20+'Todos los Datos (2)'!Z9*Hoja1!$K$21+'Todos los Datos (2)'!AE9*Hoja1!$K$22+'Todos los Datos (2)'!AJ9*Hoja1!$K$23+'Todos los Datos (2)'!AO9*Hoja1!$K$24 -> 362.68046
A10: BUGALAGRANDE | B10: ='Todos los Datos (2)'!B10*Hoja1!$K$17+'Todos los Datos (2)'!G10*Hoja1!$K$18+'Todos los Datos (2)'!L10*Hoja1!$K$19+'Todos los Datos (2)'!Q10*Hoja1!$K$20+'Todos los Datos (2)'!V10*Hoja1!$K$21+'Todos los Datos (2)'!AA10*Hoja1!$K$22+'Todos los Datos (2)'!AF10*Hoja1!$K$23+'Todos los Datos (2)'!AK10*Hoja1!$K$24 -> 119.716 | C10: ='Todos los Datos (2)'!C10*Hoja1!$K$17+'Todos los Datos (2)'!H10*Hoja1!$K$18+'Todos los Datos (2)'!M10*Hoja1!$K$19+'Todos los Datos (2)'!R10*Hoja1!$K$20+'Todos los Datos (2)'!W10*Hoja1!$K$21+'Todos los Datos (2)'!AB10*Hoja1!$K$22+'Todos los Datos (2)'!AG10*Hoja1!$K$23+'Todos los Datos (2)'!AL10*Hoja1!$K$24 -> 199.08431 | D10: ='Todos los Datos (2)'!D10*Hoja1!$K$17+'Todos los Datos (2)'!I10*Hoja1!$K$18+'Todos los Datos (2)'!N10*Hoja1!$K$19+'Todos los Datos (2)'!S10*Hoja1!$K$20+'Todos los Datos (2)'!X10*Hoja1!$K$21+'Todos los Datos (2)'!AC10*Hoja1!$K$22+'Todos los Datos (2)'!AH10*Hoja1!$K$23+'Todos los Datos (2)'!AM10*Hoja1!$K$24 -> 212.3651 | E10: ='Todos los Datos (2)'!E10*Hoja1!$K$17+'Todos los Datos (2)'!J10*Hoja1!$K$18+'Todos los Datos (2)'!O10*Hoja1!$K$19+'Todos los Datos (2)'!T10*Hoja1!$K$20+'Todos los Datos (2)'!Y10*Hoja1!$K$21+'Todos los Datos (2)'!AD10*Hoja1!$K$22+'Todos los Datos (2)'!AI10*Hoja1!$K$23+'Todos los Datos (2)'!AN10*Hoja1!$K$24 -> 199.44167 | F10: ='Todos los Datos (2)'!F10*Hoja1!$K$17+'Todos los Datos (2)'!K10*Hoja1!$K$18+'Todos los Datos (2)'!P10*Hoja1!$K$19+'Todos los Datos (2)'!U10*Hoja1!$K$20+'Todos los Datos (2)'!Z10*Hoja1!$K$21+'Todos los Datos (2)'!AE10*Hoja1!$K$22+'Todos los Datos (2)'!AJ10*Hoja1!$K$23+'Todos los Datos (2)'!AO10*Hoja1!$K$24 -> 221.85776
A11: CAICEDONIA | B11: ='Todos los Datos (2)'!B11*Hoja1!$K$17+'Todos los Datos (2)'!G11*Hoja1!$K$18+'Todos los Datos (2)'!L11*Hoja1!$K$19+'Todos los Datos (2)'!Q11*Hoja1!$K$20+'Todos los Datos (2)'!V11*Hoja1!$K$21+'Todos los Datos (2)'!AA11*Hoja1!$K$22+'Todos los Datos (2)'!AF11*Hoja1!$K$23+'Todos los Datos (2)'!AK11*Hoja1!$K$24 -> 176.03415 | C11: ='Todos los Datos (2)'!C11*Hoja1!$K$17+'Todos los Datos (2)'!H11*Hoja1!$K$18+'Todos los Datos (2)'!M11*Hoja1!$K$19+'Todos los Datos (2)'!R11*Hoja1!$K$20+'Todos los Datos (2)'!W11*Hoja1!$K$21+'Todos los Datos (2)'!AB11*Hoja1!$K$22+'Todos los Datos (2)'!AG11*Hoja1!$K$23+'Todos los Datos (2)'!AL11*Hoja1!$K$24 -> 175.74665 | D11: ='Todos los Datos (2)'!D11*Hoja1!$K$17+'Todos los Datos (2)'!I11*Hoja1!$K$18+'Todos los Datos (2)'!N11*Hoja1!$K$19+'Todos los Datos (2)'!S11*Hoja1!$K$20+'Todos los Datos (2)'!X11*Hoja1!$K$21+'Todos los Datos (2)'!AC11*Hoja1!$K$22+'Todos los Datos (2)'!AH11*Hoja1!$K$23+'Todos los Datos (2)'!AM11*Hoja1!$K$24 -> 215.52726 | E11: ='Todos los Datos (2)'!E11*Hoja1!$K$17+'Todos los Datos (2)'!J11*Hoja1!$K$18+'Todos los Datos (2)'!O11*Hoja1!$K$19+'Todos los Datos (2)'!T11*Hoja1!$K$20+'Todos los Datos (2)'!Y11*Hoja1!$K$21+'Todos los Datos (2)'!AD11*Hoja1!$K$22+'Todos los Datos (2)'!AI11*Hoja1!$K$23+'Todos los Datos (2)'!AN11*Hoja1!$K$24 -> 200.27979 | F11: ='Todos los Datos (2)'!F11*Hoja1!$K$17+'Todos los Datos (2)'!K11*Hoja1!$K$18+'Todos los Datos (2)'!P11*Hoja1!$K$19+'Todos los Datos (2)'!U11*Hoja1!$K$20+'Todos los Datos (2)'!Z11*Hoja1!$K$21+'Todos los Datos (2)'!AE11*Hoja1!$K$22+'Todos los Datos (2)'!AJ11*Hoja1!$K$23+'Todos los Datos (2)'!AO11*Hoja1!$K$24 -> 185.83455
A12: CALIMA EL DARIEN | B12: ='Todos los Datos (2)'!B12*Hoja1!$K$17+'Todos los Datos (2)'!G12*Hoja1!$K$18+'Todos los Datos (2)'!L12*Hoja1!$K$19+'Todos los Datos (2)'!Q12*Hoja1!$K$20+'Todos los Datos (2)'!V12*Hoja1!$K$21+'Todos los Datos (2)'!AA12*Hoja1!$K$22+'Todos los Datos (2)'!AF12*Hoja1!$K$23+'Todos los Datos (2)'!AK12*Hoja1!$K$24 -> 170.61349 | C12: ='Todos los Datos (2)'!C12*Hoja1!$K$17+'Todos los Datos (2)'!H12*Hoja1!$K$18+'Todos los Datos (2)'!M12*Hoja1!$K$19+'Todos los Datos (2)'!R12*Hoja1!$K$20+'Todos los Datos (2)'!W12*Hoja1!$K$21+'Todos los Datos (2)'!AB12*Hoja1!$K$22+'Todos los Datos (2)'!AG12*Hoja1!$K$23+'Todos los Datos (2)'!AL12*Hoja1!$K$24 -> 266.64972 | D12: ='Todos los Datos (2)'!D12*Hoja1!$K$17+'Todos los Datos (2)'!I12*Hoja1!$K$18+'Todos los Datos (2)'!N12*Hoja1!$K$19+'Todos los Datos (2)'!S12*Hoja1!$K$20+'Todos los Datos (2)'!X12*Hoja1!$K$21+'Todos los Datos (2)'!AC12*Hoja1!$K$22+'Todos los Datos (2)'!AH12*Hoja1!$K$23+'Todos los Datos (2)'!AM12*Hoja1!$K$24 -> 315.57819 | E12: ='Todos los Datos (2)'!E12*Hoja1!$K$17+'Todos los Datos (2)'!J12*Hoja1!$K$18+'Todos los Datos (2)'!O12*Hoja1!$K$19+'Todos los Datos (2)'!T12*Hoja1!$K$20+'Todos los Datos (2)'!Y12*Hoja1!$K$21+'Todos los Datos (2)'!AD12*Hoja1!$K$22+'Todos los Datos (2)'!AI12*Hoja1!$K$23+'Todos los Datos (2)'!AN12*Hoja1!$K$24 -> 302.46082 | F12: ='Todos los Datos (2)'!F12*Hoja1!$K$17+'Todos los Datos (2)'!K12*Hoja1!$K$18+'Todos los Datos (2)'!P12*Hoja1!$K$19+'Todos los Datos (2)'!U12*Hoja1!$K$20+'Todos los Datos (2)'!Z12*Hoja1!$K$21+'Todos los Datos (2)'!AE12*Hoja1!$K$22+'Todos los Datos (2)'!AJ12*Hoja1!$K$23+'Todos los Datos (2)'!AO12*Hoja1!$K$24 -> 274.70613
A13: CANDELARIA | B13: ='Todos los Datos (2)'!B13*Hoja1!$K$17+'Todos los Datos (2)'!G13*Hoja1!$K$18+'Todos los Datos (2)'!L13*Hoja1!$K$19+'Todos los Datos (2)'!Q13*Hoja1!$K$20+'Todos los Datos (2)'!V13*Hoja1!$K$21+'Todos los Datos (2)'!AA13*Hoja1!$K$22+'Todos los Datos (2)'!AF13*Hoja1!$K$23+'Todos los Datos (2)'!AK13*Hoja1!$K$24 -> 314.23195 | C13: ='Todos los Datos (2)'!C13*Hoja1!$K$17+'Todos los Datos (2)'!H13*Hoja1!$K$18+'Todos los Datos (2)'!M13*Hoja1!$K$19+'Todos los Datos (2)'!R13*Hoja1!$K$20+'Todos los Datos (2)'!W13*Hoja1!$K$21+'Todos los Datos (2)'!AB13*Hoja1!$K$22+'Todos los Datos (2)'!AG13*Hoja1!$K$23+'Todos los Datos (2)'!AL13*Hoja1!$K$24 -> 392.34823 | D13: ='Todos los Datos (2)'!D13*Hoja1!$K$17+'Todos los Datos (2)'!I13*Hoja1!$K$18+'Todos los Datos (2)'!N13*Hoja1!$K$19+'Todos los Datos (2)'!S13*Hoja1!$K$20+'Todos los Datos (2)'!X13*Hoja1!$K$21+'Todos los Datos (2)'!AC13*Hoja1!$K$22+'Todos los Datos (2)'!AH13*Hoja1!$K$23+'Todos los Datos (2)'!AM13*Hoja1!$K$24 -> 434.71183 | E13: ='Todos los Datos (2)'!E13*Hoja1!$K$17+'Todos los Datos (2)'!J13*Hoja1!$K$18+'Todos los Datos (2)'!O13*Hoja1!$K$19+'Todos los Datos (2)'!T13*Hoja1!$K$20+'Todos los Datos (2)'!Y13*Hoja1!$K$21+'Todos los Datos (2)'!AD13*Hoja1!$K$22+'Todos los Datos (2)'!AI13*Hoja1!$K$23+'Todos los Datos (2)'!AN13*Hoja1!$K$24 -> 421.29054 | F13: ='Todos los Datos (2)'!F13*Hoja1!$K$17+'Todos los Datos (2)'!K13*Hoja1!$K$18+'Todos los Datos (2)'!P13*Hoja1!$K$19+'Todos los Datos (2)'!U13*Hoja1!$K$20+'Todos los Datos (2)'!Z13*Hoja1!$K$21+'Todos los Datos (2)'!AE13*Hoja1!$K$22+'Todos los Datos (2)'!AJ13*Hoja1!$K$23+'Todos los Datos (2)'!AO13*Hoja1!$K$24 -> 464.33515
A14: CARTAGO | B14: ='Todos los Datos (2)'!B14*Hoja1!$K$17+'Todos los Datos (2)'!G14*Hoja1!$K$18+'Todos los Datos (2)'!L14*Hoja1!$K$19+'Todos los Datos (2)'!Q14*Hoja1!$K$20+'Todos los Datos (2)'!V14*Hoja1!$K$21+'Todos los Datos (2)'!AA14*Hoja1!$K$22+'Todos los Datos (2)'!AF14*Hoja1!$K$23+'Todos los Datos (2)'!AK14*Hoja1!$K$24 -> 198.26551 | C14: ='Todos los Datos (2)'!C14*Hoja1!$K$17+'Todos los Datos (2)'!H14*Hoja1!$K$18+'Todos los Datos (2)'!M14*Hoja1!$K$19+'Todos los Datos (2)'!R14*Hoja1!$K$20+'Todos los Datos (2)'!W14*Hoja1!$K$21+'Todos los Datos (2)'!AB14*Hoja1!$K$22+'Todos los Datos (2)'!AG14*Hoja1!$K$23+'Todos los Datos (2)'!AL14*Hoja1!$K$24 -> 230.66626 | D14: ='Todos los Datos (2)'!D14*Hoja1!$K$17+'Todos los Datos (2)'!I14*Hoja1!$K$18+'Todos los Datos (2)'!N14*Hoja1!$K$19+'Todos los Datos (2)'!S14*Hoja1!$K$20+'Todos los Datos (2)'!X14*Hoja1!$K$21+'Todos los Datos (2)'!AC14*Hoja1!$K$22+'Todos los Datos (2)'!AH14*Hoja1!$K$23+'Todos los Datos (2)'!AM14*Hoja1!$K$24 -> 227.71931 | E14: ='Todos los Datos (2)'!E14*Hoja1!$K$17+'Todos los Datos (2)'!J14*Hoja1!$K$18+'Todos los Datos (2)'!O14*Hoja1!$K$19+'Todos los Datos (2)'!T14*Hoja1!$K$20+'Todos los Datos (2)'!Y14*Hoja1!$K$21+'Todos los Datos (2)'!AD14*Hoja1!$K$22+'Todos los Datos (2)'!AI14*Hoja1!$K$23+'Todos los Datos (2)'!AN14*Hoja1!$K$24 -> 252.50014 | F14: ='Todos los Datos (2)'!F14*Hoja1!$K$17+'Todos los Datos (2)'!K14*Hoja1!$K$18+'Todos los Datos (2)'!P14*Hoja1!$K$19+'Todos los Datos (2)'!U14*Hoja1!$K$20+'Todos los Datos (2)'!Z14*Hoja1!$K$21+'Todos los Datos (2)'!AE14*Hoja1!$K$22+'Todos los Datos (2)'!AJ14*Hoja1!$K$23+'Todos los Datos (2)'!AO14*Hoja1!$K$24 -> 250.30237
A15: DAGUA | B15: ='Todos los Datos (2)'!B15*Hoja1!$K$17+'Todos los Datos (2)'!G15*Hoja1!$K$18+'Todos los Datos (2)'!L15*Hoja1!$K$19+'Todos los Datos (2)'!Q15*Hoja1!$K$20+'Todos los Datos (2)'!V15*Hoja1!$K$21+'Todos los Datos (2)'!AA15*Hoja1!$K$22+'Todos los Datos (2)'!AF15*Hoja1!$K$23+'Todos los Datos (2)'!AK15*Hoja1!$K$24 -> 145.77625 | C15: ='Todos los Datos (2)'!C15*Hoja1!$K$17+'Todos los Datos (2)'!H15*Hoja1!$K$18+'Todos los Datos (2)'!M15*Hoja1!$K$19+'Todos los Datos (2)'!R15*Hoja1!$K$20+'Todos los Datos (2)'!W15*Hoja1!$K$21+'Todos los Datos (2)'!AB15*Hoja1!$K$22+'Todos los Datos (2)'!AG15*Hoja1!$K$23+'Todos los Datos (2)'!AL15*Hoja1!$K$24 -> 183.07148 | D15: ='Todos los Datos (2)'!D15*Hoja1!$K$17+'Todos los Datos (2)'!I15*Hoja1!$K$18+'Todos los Datos (2)'!N15*Hoja1!$K$19+'Todos los Datos (2)'!S15*Hoja1!$K$20+'Todos los Datos (2)'!X15*Hoja1!$K$21+'Todos los Datos (2)'!AC15*Hoja1!$K$22+'Todos los Datos (2)'!AH15*Hoja1!$K$23+'Todos los Datos (2)'!AM15*Hoja1!$K$24 -> 173.42278 | E15: ='Todos los Datos (2)'!E15*Hoja1!$K$17+'Todos los Datos (2)'!J15*Hoja1!$K$18+'Todos los Datos (2)'!O15*Hoja1!$K$19+'Todos los Datos (2)'!T15*Hoja1!$K$20+'Todos los Datos (2)'!Y15*Hoja1!$K$21+'Todos los Datos (2)'!AD15*Hoja1!$K$22+'Todos los Datos (2)'!AI15*Hoja1!$K$23+'Todos los Datos (2)'!AN15*Hoja1!$K$24 -> 174.50029 | F15: ='Todos los Datos (2)'!F15*Hoja1!$K$17+'Todos los Datos (2)'!K15*Hoja1!$K$18+'Todos los Datos (2)'!P15*Hoja1!$K$19+'Todos los Datos (2)'!U15*Hoja1!$K$20+'Todos los Datos (2)'!Z15*Hoja1!$K$21+'Todos los Datos (2)'!AE15*Hoja1!$K$22+'Todos los Datos (2)'!AJ15*Hoja1!$K$23+'Todos los Datos (2)'!AO15*Hoja1!$K$24 -> 149.29121 | K15: {=TRANSPOSE(INDEX(IF(ISNUMBER(IFERROR(FIND(J17:J24,IF(IFERROR(FIND(B$1,'Todos los Datos (2)'!B1:AO1),0)<>0,'Todos los Datos (2)'!B1:AO1)),"")),1,0)*$K$17:$K$24,_xlfn.SEQUENCE(8),_xlfn.SEQUENCE(8)*5-4))} -> 0.00088834167 | L15: 0.018373156 | M15: 0.42496023 | N15: 0.1122109 | O15: 0.056231868 | P15: 0.011104589 | Q15: 0.37623091 | R15: 0
A16: EL AGUILA | B16: ='Todos los Datos (2)'!B16*Hoja1!$K$17+'Todos los Datos (2)'!G16*Hoja1!$K$18+'Todos los Datos (2)'!L16*Hoja1!$K$19+'Todos los Datos (2)'!Q16*Hoja1!$K$20+'Todos los Datos (2)'!V16*Hoja1!$K$21+'Todos los Datos (2)'!AA16*Hoja1!$K$22+'Todos los Datos (2)'!AF16*Hoja1!$K$23+'Todos los Datos (2)'!AK16*Hoja1!$K$24 -> 21.979662 | C16: ='Todos los Datos (2)'!C16*Hoja1!$K$17+'Todos los Datos (2)'!H16*Hoja1!$K$18+'Todos los Datos (2)'!M16*Hoja1!$K$19+'Todos los Datos (2)'!R16*Hoja1!$K$20+'Todos los Datos (2)'!W16*Hoja1!$K$21+'Todos los Datos (2)'!AB16*Hoja1!$K$22+'Todos los Datos (2)'!AG16*Hoja1!$K$23+'Todos los Datos (2)'!AL16*Hoja1!$K$24 -> 45.501434 | D16: ='Todos los Datos (2)'!D16*Hoja1!$K$17+'Todos los Datos (2)'!I16*Hoja1!$K$18+'Todos los Datos (2)'!N16*Hoja1!$K$19+'Todos los Datos (2)'!S16*Hoja1!$K$20+'Todos los Datos (2)'!X16*Hoja1!$K$21+'Todos los Datos (2)'!AC16*Hoja1!$K$22+'Todos los Datos (2)'!AH16*Hoja1!$K$23+'Todos los Datos (2)'!AM16*Hoja1!$K$24 -> 52.130748 | E16: ='Todos los Datos (2)'!E16*Hoja1!$K$17+'Todos los Datos (2)'!J16*Hoja1!$K$18+'Todos los Datos (2)'!O16*Hoja1!$K$19+'Todos los Datos (2)'!T16*Hoja1!$K$20+'Todos los Datos (2)'!Y16*Hoja1!$K$21+'Todos los Datos (2)'!AD16*Hoja1!$K$22+'Todos los Datos (2)'!AI16*Hoja1!$K$23+'Todos los Datos (2)'!AN16*Hoja1!$K$24 -> 73.038102 | F16: ='Todos los Datos (2)'!F16*Hoja1!$K$17+'Todos los Datos (2)'!K16*Hoja1!$K$18+'Todos los Datos (2)'!P16*Hoja1!$K$19+'Todos los Datos (2)'!U16*Hoja1!$K$20+'Todos los Datos (2)'!Z16*Hoja1!$K$21+'Todos los Datos (2)'!AE16*Hoja1!$K$22+'Todos los Datos (2)'!AJ16*Hoja1!$K$23+'Todos los Datos (2)'!AO16*Hoja1!$K$24 -> 71.531473 | J16: Porcentajes
